<?xml version="1.0" ?>
<robot name="cartrasche" xmlns:xacro="http://www.ros.org/wiki/xacro">

<xacro:include filename="$(find cartrasche_description)/urdf/materials.xacro" />
<xacro:include filename="$(find cartrasche_description)/urdf/cartrasche.trans" />
<xacro:include filename="$(find cartrasche_description)/urdf/cartrasche.gazebo" />
<link name="base_link">
  <inertial>
    <origin xyz="-0.17500000000000093 0.1465379545676244 -0.04167420563757363" rpy="0 0 0"/>
    <mass value="14.854275644982799"/>
    <inertia ixx="0.311009" iyy="0.269977" izz="0.551767" ixy="0.0" iyz="0.004993" ixz="-0.0"/>
  </inertial>
  <visual>
    <origin xyz="0 0 0" rpy="0 0 0"/>
    <geometry>
      <mesh filename="package://cartrasche_description/meshes/base_link.stl" scale="0.001 0.001 0.001"/>
    </geometry>
    <material name="silver"/>
  </visual>
  <collision>
    <origin xyz="0 0 0" rpy="0 0 0"/>
    <geometry>
      <mesh filename="package://cartrasche_description/meshes/base_link.stl" scale="0.001 0.001 0.001"/>
    </geometry>
  </collision>
</link>

<link name="Wheel_L_1">
  <inertial>
    <origin xyz="-0.004962223004344377 3.726186026398182e-15 6.522560269672795e-16" rpy="0 0 0"/>
    <mass value="3.060084322980661"/>
    <inertia ixx="0.004797" iyy="0.0028" izz="0.0028" ixy="0.0" iyz="0.0" ixz="0.0"/>
  </inertial>
  <visual>
    <origin xyz="-0.032 -0.06 0.063" rpy="0 0 0"/>
    <geometry>
      <mesh filename="package://cartrasche_description/meshes/Wheel_L_1.stl" scale="0.001 0.001 0.001"/>
    </geometry>
    <material name="silver"/>
  </visual>
  <collision>
    <origin xyz="-0.032 -0.06 0.063" rpy="0 0 0"/>
    <geometry>
      <mesh filename="package://cartrasche_description/meshes/Wheel_L_1.stl" scale="0.001 0.001 0.001"/>
    </geometry>
  </collision>
</link>

<link name="Wheel_R_1">
  <inertial>
    <origin xyz="0.004962223004343791 -4.198030811863873e-15 1.3877787807814457e-17" rpy="0 0 0"/>
    <mass value="3.060084322980661"/>
    <inertia ixx="0.004797" iyy="0.0028" izz="0.0028" ixy="0.0" iyz="-0.0" ixz="0.0"/>
  </inertial>
  <visual>
    <origin xyz="0.382 -0.06 0.063" rpy="0 0 0"/>
    <geometry>
      <mesh filename="package://cartrasche_description/meshes/Wheel_R_1.stl" scale="0.001 0.001 0.001"/>
    </geometry>
    <material name="silver"/>
  </visual>
  <collision>
    <origin xyz="0.382 -0.06 0.063" rpy="0 0 0"/>
    <geometry>
      <mesh filename="package://cartrasche_description/meshes/Wheel_R_1.stl" scale="0.001 0.001 0.001"/>
    </geometry>
  </collision>
</link>

<joint name="Rotate1" type="continuous">
  <origin xyz="0.032 0.06 -0.063" rpy="0 0 0"/>
  <parent link="base_link"/>
  <child link="Wheel_L_1"/>
  <axis xyz="1.0 0.0 0.0"/>
</joint>

<joint name="Rotate2" type="continuous">
  <origin xyz="-0.382 0.06 -0.063" rpy="0 0 0"/>
  <parent link="base_link"/>
  <child link="Wheel_R_1"/>
  <axis xyz="-1.0 -0.0 0.0"/>
</joint>

</robot>
